Workbook
Name enum_ListDays: #REF!
Name enum_ListIdentifier: #REF!
Name enum_ListMonth: #REF!
Name enum_ListOfCurrencies: #REF!
Name enum_ListYear: #REF!
Name FuelList: tblConversions[Item]
Name FuelList: tblConversions[Item]
Name FuelList: tblConversions[Item]
Name FuelList: tblConversions[Item]
Name FuelList: tblConversions[Item]
Name FuelList: tblConversions[Item]
Name template_label_always_to_be_reported: #REF!
Name template_label_currency_of_the_monetary_values_in_the_report: #REF!
Name template_label_description_of_how_it_applies_these_principles: #REF!
Name template_label_ending_month: #REF!
Name template_label_ending_year: #REF!
Name template_label_identifier_of_the_reporting_entity: #REF!
Name template_label_information_on_the_report_necessary_for_xbrl: #REF!
Name template_label_name_of_the_reporting_entity: #REF!
Name template_label_reporting_period_end_date: #REF!
Name template_label_reporting_period_start_date: #REF!
Name template_label_starting_day: #REF!
Name template_label_starting_month: #REF!
Name template_label_starting_year: #REF!
Name template_label_undertaking_applies_circular_economy_principles: #REF!

Sheet Home
C2: TEXTILE EXPORTER ENVIRONMENTAL DASHBOARD
B4: ∷ | C4: ⚡ Energy | D4: 🌱Carbon Footprint | E4: 💧Water | F4: 🗑️ Waste & Materials | G4: 🌏 Biodiversity
C6: =Metrics!C15 -> 928.7775 | D6: =Waste_Materials!$H$19 -> 7.5:5.1 | E6: =Water!$C$6 -> 185 m3 | F6: =Biodiversity!F6 -> 0.89285714 | G6: =Waste_Materials!$D$6 -> 0.08 MT
C7: ENERGY USE MWh/MN$ | D7: RECYCLED/DISPOSED | E7: WATER CONSUMPTION | F7: LAND IN SENSITIVE AREA | G7: HAZARDOUS WASTE
H18: =Water!$H$18 -> Anticipated effect from water & marine resources
H19: =Water!$H$19 -> 100000

Sheet Energy
C2: TEXTILE EXPORTER ENVIRONMENTAL DASHBOARD
B4: ∷ | C4: ⚡ Energy | D4: 🌱Carbon Footprint | E4: 💧Water | F4: 🗑️ Waste & Materials | G4: 🌏 Biodiversity
C6: =Metrics!C8 -> 5000000 | E6: =Metrics!C14 -> 4643.8875 | F6: =Metrics!C43 -> 0.5 | G6: 0.17
C7: REVENUE BASELINE | E7: TOTAL ENERGY (MWh) | F7: RENEWABLE TARGET | G7: TARGET ACHIEVED
H18: Total energy use per $million of revenue
H19: =Metrics!C15 -> 928.7775

Sheet Carbon
C2: TEXTILE EXPORTER ENVIRONMENTAL DASHBOARD
B4: ∷ | C4: ⚡ Energy | D4: 🌱Carbon Footprint | E4: 💧Water | F4: 🗑️ Waste & Materials | G4: 🌏 Biodiversity
C6: =Metrics!C30 -> 10.120025 | E6: =Metrics!C29 -> 50.600127 | F6: =Metrics!C40 -> 0.1 | G6: =Metrics!C42 -> 100000
C7: EMISSIONS INTENSITY PER $MN OF REVENUE | E7: TOTAL GHG IN tCO2e | F7: GHG REDUCTION TARGET | G7: INVESTMENT TARGET
H18: =Metrics!B41 -> Financial effects from climate risks (in $US)
H19: =Metrics!C41 -> 250000

Sheet Water
C2: TEXTILE EXPORTER ENVIRONMENTAL DASHBOARD
B4: ∷ | C4: ⚡ Energy | D4: 🌱Carbon Footprint | E4: 💧Water | F4: 🗑️ Waste & Materials | G4: 🌏 Biodiversity
C6: =_xlfn.CONCAT(Metrics!C52," ", ROUGH!C2) -> 185 m3 | E6: =Metrics!C51/Metrics!C52 -> 1 | F6: =Metrics!C59 -> -0.3 | G6: =Metrics!C60 -> -0.25
C7: TOTAL WATER CONSUMPTION | E7: RECYCLE RATIO | F7: WITHDRAWAL TARGET | G7: DISCHARGE TARGET
H18: =Metrics!B61 -> Anticipated effect from water & marine resources
H19: =Metrics!C61 -> 100000

Sheet Waste_Materials
C2: TEXTILE EXPORTER ENVIRONMENTAL DASHBOARD
B4: ∷ | C4: ⚡ Energy | D4: 🌱Carbon Footprint | E4: 💧Water | F4: 🗑️ Waste & Materials | G4: 🌏 Biodiversity
C6: =_xlfn.CONCAT(Metrics!C70," ", ROUGH!C3) -> 12.5525 MT | D6: =_xlfn.CONCAT(Metrics!C79," ", ROUGH!C3) -> 0.08 MT | E6: =Metrics!C91 -> 0.17391304 | F6: =_xlfn.CONCAT(Metrics!C94," ", ROUGH!C3) -> 182 MT | G6: =_xlfn.CONCAT(Metrics!C88," ", ROUGH!C3) -> 29 MT
C7: NON-HAZARDOUS WASTE | D7: HAZARDOUS WASTE | E7: SINGLE-USE MATERIALS | F7: MATERIAL USED | G7: RECYCLED MATERIAL
H18: RECYCLED WASTE VS DISPOSED WASTE RATIO
H19: =ROUGH!F2 & ":" & ROUGH!F3 -> 7.5:5.1

Sheet Biodiversity
C2: TEXTILE EXPORTER ENVIRONMENTAL DASHBOARD
B4: ∷ | C4: ⚡ Energy | D4: 🌱Carbon Footprint | E4: 💧Water | F4: 🗑️ Waste & Materials | G4: 🌏 Biodiversity
C6: =Metrics!C10 -> Mumbai | E6: =_xlfn.CONCAT(Metrics!C100," ",ROUGH!C4) -> 280 m2 | F6: =Metrics!C98/Metrics!C100 -> 0.89285714 | G6: =_xlfn.CONCAT(Metrics!C99," ",ROUGH!C4) -> 30 m2
C7: LOCATION OF MANUFACTURING PLANT | E7: SIZE OF FACILITY | F7: LAND IN SENSITIVE AREA | G7: SEALED/ARTIFICIAL AREA
F9: POLICY CHECK
F12: =Metrics!B103 -> Does the Organisation Source Priority Raw Materials From Deforestation Free Areas? | G12: =Metrics!C103 -> YES
F15: =Metrics!B104 -> Any Incidents of Deforestation? | G15: =Metrics!C104 -> NO
F17: =Metrics!B105 -> Any Species Under Global Extinction Risk Affected? | G17: =Metrics!C105 -> NO
H18: =Metrics!B61 -> Anticipated effect from water & marine resources
H19: =Metrics!C61 -> 100000

Sheet Metrics
A1: SECTION IDs | B1: Metric Names | C1: Values | D1: Validation | E1: Remarks (if any)
A3: A | B3: GENERAL INFORMATION
A4: A.1 | B4: ABOUT THE COMPANY
A5: A.1.1 | B5: Name of the reporting entity | C5: Textile Exporter | D5: =IF(C5="",ROUGH!$C$6,ROUGH!$C$7) -> OK
A6: A.1.2 | B6: Company registration no | C6: DUMMY_NO | D6: =IF(C6="",ROUGH!$C$6,ROUGH!$C$7) -> OK
A7: A.1.3 | B7: Company Type | C7: LLP | D7: =IF(C7="",ROUGH!$C$6,ROUGH!$C$7) -> OK
A8: A.1.4 | B8: Company Revenue (as per last annual report) | C8: 5000000 | D8: =IF(C8="",ROUGH!$C$6,ROUGH!$C$7) -> OK
A9: A.1.5 | B9: Revenue Currency Code | C9: US dollar | D9: =IF(C9="",ROUGH!$C$6,ROUGH!$C$7) -> OK | E9: Revenue currency is used in dollars due to availability of most emission factors in dollar values
A10: A.1.6 | B10: Location of Manufacturing Plant | C10: Mumbai | D10: =IF(C10="",ROUGH!$C$6,ROUGH!$C$7) -> OK
A12: B | B12: CLIMATE CHANGE
A13: B.1 | B13: Energy
A14: B.1.1 | B14: Total energy consumption (in MWh) | C14: =SUM(Inputs!L6:L14) -> 4643.8875 | D14: =IF(C14="",ROUGH!$C$6,ROUGH!$C$7) -> OK
A15: B.1.2 | B15: Total energy use per $million of revenue | C15: =(C14/(C8/1000000)) -> 928.7775 | D15: =IF(C15="",ROUGH!$C$6,ROUGH!$C$7) -> OK
A16: B.1.3 | B16: Percentage of renewable energy (on-site) | C16: =(SUM(Inputs!N6:N14)/C14) -> 0.1292021 | D16: =IF(C16="",ROUGH!$C$6,ROUGH!$C$7) -> OK
A17: B.1.4 | B17: Total Electricity Consumption | C17: =SUM(Inputs!L6:L8) -> 4600 | D17: =IF(C17="",ROUGH!$C$6,ROUGH!$C$7) -> OK
A18: B.1.5 | B18: Total Renewable Electricity | C18: =SUM(Inputs!N6:N8) -> 600 | D18: =IF(C18="",ROUGH!$C$6,ROUGH!$C$7) -> OK
A19: B.1.6 | B19: Total Non-Renewable Electricity | C19: =SUM(Inputs!O6:O8) -> 4000 | D19: =IF(C19="",ROUGH!$C$6,ROUGH!$C$7) -> OK
A20: B.1.7 | B20: Fuel used (on-site) in MWh | C20: =SUM(Inputs!N11:O14) -> 43.8875 | D20: =IF(C20="",ROUGH!$C$6,ROUGH!$C$7) -> OK
A22: B.2 | B22: Green House Gas Emissions
A23: B.2.1 | B23: Gross Scope 1 GHG emissions in tCO2e (Direct) | C23: =SUMIFS(Inputs!M:M, Inputs!D:D, "Scope 1") -> 23.964548 | D23: =IF(C23="",ROUGH!$C$6,ROUGH!$C$7) -> OK
A24: B.2.2 | B24: Gross Scope 2 GHG emissions in tCO2e (Location-based) | C24: =SUMIFS(Inputs!M:M, Inputs!D:D, "Scope 2: Location") -> 3.24 | D24: =IF(C24="",ROUGH!$C$6,ROUGH!$C$7) -> OK
A25: B.2.3 | B25: Gross Indirect Scope 3 GHG emissions in tCO2e (Business Travels) | C25: =SUMIFS(Inputs!M:M, Inputs!D:D, "Scope 3", Inputs!E:E, "Business Travels") -> 19.320179 | D25: =IF(C25="",ROUGH!$C$6,ROUGH!$C$7) -> OK
A26: B.2.4 | B26: Gross Indirect Scope 3 GHG emissions in tCO2e (Upstream Transport) | C26: =SUMIFS(Inputs!M:M, Inputs!D:D, "Scope 3", Inputs!E:E, "Upstream Transport") -> 4.0754 | D26: =IF(C26="",ROUGH!$C$6,ROUGH!$C$7) -> OK
A27: B.2.5 | B27: Total GHG emissions in tCO2e (Scope 1 + 2) | C27: =SUM(C23:C24) -> 27.204548 | D27: =IF(C27="",ROUGH!$C$6,ROUGH!$C$7) -> OK
A28: B.2.6 | B28: Total GHG emissions in tCO2e (Scope 3) | C28: =C25+C26 -> 23.395579 | D28: =IF(C28="",ROUGH!$C$6,ROUGH!$C$7) -> OK
A29: B.2.7 | B29: Total GHG emssions in tCO2e (Scope 1+Scope 2+ Scope3) | C29: =C27+C28 -> 50.600127 | D29: =IF(C29="",ROUGH!$C$6,ROUGH!$C$7) -> OK
A30: B.2.8 | B30: GHG emissions intensity (per $million of revenue): | C30: =C29 / (C8 / 1000000) -> 10.120025 | D30: =IF(C30="",ROUGH!$C$6,ROUGH!$C$7) -> OK
A31: B.2.9 | B31: GHG Removals / Carbon credits retired: | C31: =SUMIFS(Inputs!M:M, Inputs!D:D, "Removals") -> -100 | D31: =IF(C31="",ROUGH!$C$6,ROUGH!$C$7) -> OK
A33: B.3 | B33: Pollution to Air, Water and Soil
A34: B.3.1 | B34: Air pollutant Nitrogen Oxides (NOx) in kg | C34: =SUMIFS(Inputs!L:L, Inputs!E:E,"NOx") -> 50 | D34: =IF(C34="",ROUGH!$C$6,ROUGH!$C$7) -> OK
A35: B.3.2 | B35: Air pollutants (SOx) in kg | C35: =SUMIFS(Inputs!L:L, Inputs!E:E, "SOx") -> 20 | D35: =IF(C35="",ROUGH!$C$6,ROUGH!$C$7) -> OK
A36: B.3.3 | B36: Particulate Matter (PM10 / PM2.5) in kg | C36: =SUMIFS(Inputs!L:L, Inputs!E:E, "PM10/PM2.5") -> 100 | D36: =IF(C36="",ROUGH!$C$6,ROUGH!$C$7) -> OK
A37: B.3.4 | B37: Emissions to water in kg (for e.g. Nitrates) | C37: =SUMIFS(Inputs!L:L, Inputs!B:B, Metrics!B37) -> 125 | D37: =IF(C37="",ROUGH!$C$6,ROUGH!$C$7) -> OK
A39: B.4 | B39: Climate Goals and Risks
A40: B.3.1 | B40: GHG reduction target and time frame (per cent per year) | C40: =_xlfn.XLOOKUP(Metrics!B40, Inputs!B:B, Inputs!L:L, "") -> 0.1 | D40: =IF(C40="",ROUGH!$C$6,ROUGH!$C$7) -> OK
A41: B.3.2 | B41: Financial effects from climate risks (in $US) | C41: =_xlfn.XLOOKUP(Metrics!B41, Inputs!B:B, Inputs!L:L, "") -> 250000 | D41: =IF(C41="",ROUGH!$C$6,ROUGH!$C$7) -> OK
A42: B.3.3 | B42: Investment allocated to transition plan (in $US) | C42: =_xlfn.XLOOKUP(Metrics!B42, Inputs!B:B, Inputs!L:L, "") -> 100000 | D42: =IF(C42="",ROUGH!$C$6,ROUGH!$C$7) -> OK
A43: B.3.4 | B43: Increase Renewable Electricity by 2027 | C43: 0.5 | D43: =IF(C43="",ROUGH!$C$6,ROUGH!$C$7) -> OK
A45: C | B45: WATER AND MARINE RESOURCES
A46: C.1 | B46: Water withdrawls
...

Sheet Inputs
A1: Sl. No | B1: SOURCE | C1: STATE | D1: CATEGORY | E1: TYPE | F1: UNIT | G1: INPUT VALUE 1 | H1: INPUT VALUE 2 | I1: TOTAL INPUTS | J1: CONVERSION FACTOR | K1: GHG FACTOR | L1: Total Converted Value | M1: Total GHG Value (in tCO2e) | N1: Input Value 1 (Final) | O1: Input Value 2 (Final)
G2: Enter Manually | H2: Enter Manually | I2: Auto calculated | J2: Auto calculated | K2: Auto calculated | L2: Auto calculated | M2: Auto calculated | N2: Auto calculated | O2: Auto calculated
A3: B. | B3: CLIMATE CHANGE
A4: B.1 | B4: Energy
B5: Electricity Consumed | G5: Renewable Energy | H5: Non-Renewavle Energy | I5: Total Energy in MWh | J5: Energy Factor | K5: GHG Factor kgCo2e | L5: Total Energy Consumed | M5: Total GHG Value (in tCO2e) | N5: Total Renewable Energy Consumed (MWh) | O5: Total Non-Renewable Energy Consumed (MWh)
B6: Electricity (Grid) | C6: =_xlfn.XLOOKUP(B6, tblConversions[Item], tblConversions[State], "" ) -> Energy | D6: =_xlfn.XLOOKUP(B6, tblConversions[Item], tblConversions[Category], "") -> Scope 2: Location | E6: =_xlfn.XLOOKUP(B6, tblConversions[Item], tblConversions[Type], "") -> Non-Renewable | F6: =_xlfn.XLOOKUP(B6, tblConversions[Item], tblConversions[Unit], "") -> MWh | G6: 0 | H6: 4000 | I6: =G6+H6 -> 4000 | J6: =_xlfn.XLOOKUP(B6, tblConversions[Item], tblConversions[Multiplier], 0) -> 1 | K6: =_xlfn.XLOOKUP(B6, tblConversions[Item], tblConversions[GHG Factor (t CO2e per Unit)], 0) -> 0.81 | L6: =I6*J6 -> 4000 | M6: =IF(E6="Renewable", 0, (H6 * K6) / 1000) -> 3.24 | N6: =IF(E6="Non-Renewable", 0, L6) -> 0 | O6: =IF(E6="Renewable", 0, L6) -> 4000
B7: On-Site Solar | C7: =_xlfn.XLOOKUP(B7, tblConversions[Item], tblConversions[State], "" ) -> Energy | D7: =_xlfn.XLOOKUP(B7, tblConversions[Item], tblConversions[Category], "") -> Scope 1 | E7: =_xlfn.XLOOKUP(B7, tblConversions[Item], tblConversions[Type], "") -> Renewable | F7: =_xlfn.XLOOKUP(B7, tblConversions[Item], tblConversions[Unit], "") -> MWh | G7: 600 | H7: 0 | I7: =G7+H7 -> 600 | J7: 1 | K7: =_xlfn.XLOOKUP(B7, tblConversions[Item], tblConversions[GHG Factor (t CO2e per Unit)], 0) -> 0 | L7: =I7*J7 -> 600 | M7: =IF(E7="Renewable", 0, (H7 * K7) / 1000) -> 0 | N7: =IF(E7="Non-Renewable", 0, L7) -> 600 | O7: =IF(E7="Renewable", 0, L7) -> 0
B8: On-Site Wind Electricity | C8: =_xlfn.XLOOKUP(B8, tblConversions[Item], tblConversions[State], "" ) -> Energy | D8: =_xlfn.XLOOKUP(B8, tblConversions[Item], tblConversions[Category], "") -> Scope 1 | E8: =_xlfn.XLOOKUP(B8, tblConversions[Item], tblConversions[Type], "") -> Renewable | F8: =_xlfn.XLOOKUP(B8, tblConversions[Item], tblConversions[Unit], "") -> MWh | G8: 0 | H8: 0 | I8: =G8+H8 -> 0 | J8: 1 | K8: =_xlfn.XLOOKUP(B8, tblConversions[Item], tblConversions[GHG Factor (t CO2e per Unit)], 0) -> 0 | L8: =I8*J8 -> 0 | M8: =IF(E8="Renewable", 0, (H8 * K8) / 1000) -> 0 | N8: =IF(E8="Non-Renewable", 0, L8) -> 0 | O8: =IF(E8="Renewable", 0, L8) -> 0
C9: =_xlfn.XLOOKUP(B9, tblConversions[Item], tblConversions[State], "" )
B10: Fuels Used Inside The Facility | C10: =_xlfn.XLOOKUP(B10, tblConversions[Item], tblConversions[State], "" )
B11: Kerosene | C11: =_xlfn.XLOOKUP(B11, tblConversions[Item], tblConversions[State], "" ) -> Liquid | D11: =_xlfn.XLOOKUP(B11, tblConversions[Item], tblConversions[Category], "") -> Scope 1 | E11: =_xlfn.XLOOKUP(B11, tblConversions[Item], tblConversions[Type], "") -> Non-Renewable | F11: =_xlfn.XLOOKUP(B11, tblConversions[Item], tblConversions[Unit], "") -> Litres | G11: 0 | H11: 1000 | I11: =G11+H11 -> 1000 | J11: =_xlfn.XLOOKUP(B11, tblConversions[Item], tblConversions[Multiplier], 0) -> 0.0097 | K11: =_xlfn.XLOOKUP(B11, tblConversions[Item], tblConversions[GHG Factor (t CO2e per Unit)], 0) -> 2.518 | L11: =I11*J11 -> 9.7 | M11: =IF(E11="Renewable", 0, (I11 * K11) / 1000) -> 2.518 | N11: =IF(E11="Non-Renewable", 0, L11) -> 0 | O11: =IF(E11="Renewable", 0, L11) -> 9.7
B12: Diesel | C12: =_xlfn.XLOOKUP(B12, tblConversions[Item], tblConversions[State], "" ) -> Liquid | D12: =_xlfn.XLOOKUP(B12, tblConversions[Item], tblConversions[Category], "") -> Scope 1 | E12: =_xlfn.XLOOKUP(B12, tblConversions[Item], tblConversions[Type], "") -> Non-Renewable | F12: =_xlfn.XLOOKUP(B12, tblConversions[Item], tblConversions[Unit], "") -> Litres | G12: 0 | H12: 2000 | I12: =G12+H12 -> 2000 | J12: =_xlfn.XLOOKUP(B12, tblConversions[Item], tblConversions[Multiplier], 0) -> 0.0106 | K12: =_xlfn.XLOOKUP(B12, tblConversions[Item], tblConversions[GHG Factor (t CO2e per Unit)], 0) -> 2.66155 | L12: =I12*J12 -> 21.2 | M12: =IF(E12="Renewable", 0, (H12 * K12) / 1000) -> 5.3231 | N12: =IF(E12="Non-Renewable", 0, L12) -> 0 | O12: =IF(E12="Renewable", 0, L12) -> 21.2
B13: LPG | C13: =_xlfn.XLOOKUP(B13, tblConversions[Item], tblConversions[State], "" ) -> Liquid | D13: =_xlfn.XLOOKUP(B13, tblConversions[Item], tblConversions[Category], "") -> Scope 1 | E13: =_xlfn.XLOOKUP(B13, tblConversions[Item], tblConversions[Type], "") -> Non-Renewable | F13: =_xlfn.XLOOKUP(B13, tblConversions[Item], tblConversions[Unit], "") -> kg | G13: 0 | H13: 475 | I13: =G13+H13 -> 475 | J13: =_xlfn.XLOOKUP(B13, tblConversions[Item], tblConversions[Multiplier], 0) -> 0.0137 | K13: =_xlfn.XLOOKUP(B13, tblConversions[Item], tblConversions[GHG Factor (t CO2e per Unit)], 0) -> 2.93936 | L13: =I13*J13 -> 6.5075 | M13: =IF(E13="Renewable", 0, (H13 * K13) / 1000) -> 1.396196 | N13: =IF(E13="Non-Renewable", 0, L13) -> 0 | O13: =IF(E13="Renewable", 0, L13) -> 6.5075
B14: Natural Gas | C14: =_xlfn.XLOOKUP(B14, tblConversions[Item], tblConversions[State], "" ) -> Gas | D14: =_xlfn.XLOOKUP(B14, tblConversions[Item], tblConversions[Category], "") -> Scope 1 | E14: =_xlfn.XLOOKUP(B14, tblConversions[Item], tblConversions[Type], "") -> Non-Renewable | F14: =_xlfn.XLOOKUP(B14, tblConversions[Item], tblConversions[Unit], "") -> m³ | G14: 0 | H14: 600 | I14: =G14+H14 -> 600 | J14: =_xlfn.XLOOKUP(B14, tblConversions[Item], tblConversions[Multiplier], 0) -> 0.0108 | K14: =_xlfn.XLOOKUP(B14, tblConversions[Item], tblConversions[GHG Factor (t CO2e per Unit)], 0) -> 2.04542 | L14: =I14*J14 -> 6.48 | M14: =IF(E14="Renewable", 0, (H14 * K14) / 1000) -> 1.227252 | N14: =IF(E14="Non-Renewable", 0, L14) -> 0 | O14: =IF(E14="Renewable", 0, L14) -> 6.48
C15: =_xlfn.XLOOKUP(B15, tblConversions[Item], tblConversions[State], "" )
A16: B.2 | B16: Green House Gases | C16: =_xlfn.XLOOKUP(B16, tblConversions[Item], tblConversions[State], "" )
C17: =_xlfn.XLOOKUP(B17, tblConversions[Item], tblConversions[State], "" ) | G17: Electric/Hybrid Transport | H17: Fossil-fuel based transport | I17: Total Input Value | J17: Hyrbid/Electric GHG emission factor (kgCo2e/$) | K17: Fossil fuel GHG emission factor (kgCo2e/unit) | L17: NA | M17: TOTAL GHG (EV + Hybrid + Fossil) in tCO2e/$ | N17: NA | O17: NA
B18: Purchased Goods | C18: =_xlfn.XLOOKUP(B18, tblConversions[Item], tblConversions[State], "" ) -> NA | D18: =_xlfn.XLOOKUP(B18, tblConversions[Item], tblConversions[Category], "") -> Scope 3 | E18: =_xlfn.XLOOKUP(B18, tblConversions[Item], tblConversions[Type], "") -> Purchased Goods | F18: =_xlfn.XLOOKUP(B18, tblConversions[Item], tblConversions[Unit], "") -> USD | G18: 0 | H18: 100000 | I18: =G18+H18 -> 100000 | J18: =_xlfn.XLOOKUP(B18, tblConversions[Item], tblConversions[Multiplier], 0) -> 0 | K18: =_xlfn.XLOOKUP(B18, tblConversions[Item], tblConversions[GHG Factor (t CO2e per Unit)], 0) -> 0.45 | L18: NA | M18: =((H18 * K18) / 1000)+(G18*J18)/1000 -> 45 | N18: NA | O18: NA
B19: Refrigerant (R-32) | C19: =_xlfn.XLOOKUP(B19, tblConversions[Item], tblConversions[State], "" ) -> Liquid | D19: =_xlfn.XLOOKUP(B19, tblConversions[Item], tblConversions[Category], "") -> Scope 1 | E19: =_xlfn.XLOOKUP(B19, tblConversions[Item], tblConversions[Type], "") -> Direct Fugitive Emissions | F19: =_xlfn.XLOOKUP(B19, tblConversions[Item], tblConversions[Unit], "") -> kg | G19: 0 | H19: 20 | I19: =G19+H19 -> 20 | J19: =_xlfn.XLOOKUP(B19, tblConversions[Item], tblConversions[Multiplier], 0) -> 0 | K19: =_xlfn.XLOOKUP(B19, tblConversions[Item], tblConversions[GHG Factor (t CO2e per Unit)], 0) -> 675 | L19: NA | M19: =((H19 * K19) / 1000)+(G19*J19)/1000 -> 13.5 | N19: NA | O19: NA
B20: Upstream emissions from road transport | C20: =_xlfn.XLOOKUP(B20, tblConversions[Item], tblConversions[State], "" ) -> NA | D20: =_xlfn.XLOOKUP(B20, tblConversions[Item], tblConversions[Category], "") -> Scope 3 | E20: =_xlfn.XLOOKUP(B20, tblConversions[Item], tblConversions[Type], "") -> Upstream Transport | F20: =_xlfn.XLOOKUP(B20, tblConversions[Item], tblConversions[Unit], "") -> USD | G20: 0 | H20: 1500 | I20: =G20+H20 -> 1500 | J20: =_xlfn.XLOOKUP(B20, tblConversions[Item], tblConversions[Multiplier], 0) -> 0 | K20: =_xlfn.XLOOKUP(B20, tblConversions[Item], tblConversions[GHG Factor (t CO2e per Unit)], 0) -> 1.9836 | L20: NA | M20: =((H20 * K20) / 1000)+(G20*J20)/1000 -> 2.9754 | N20: NA | O20: NA
B21: Upstream emissions from air transport | C21: =_xlfn.XLOOKUP(B21, tblConversions[Item], tblConversions[State], "" ) -> NA | D21: =_xlfn.XLOOKUP(B21, tblConversions[Item], tblConversions[Category], "") -> Scope 3 | E21: =_xlfn.XLOOKUP(B21, tblConversions[Item], tblConversions[Type], "") -> Upstream Transport | F21: =_xlfn.XLOOKUP(B21, tblConversions[Item], tblConversions[Unit], "") -> USD | G21: 0 | H21: 5000 | I21: =G21+H21 -> 5000 | J21: =_xlfn.XLOOKUP(B21, tblConversions[Item], tblConversions[Multiplier], 0) -> 0 | K21: =_xlfn.XLOOKUP(B21, tblConversions[Item], tblConversions[GHG Factor (t CO2e per Unit)], 0) -> 0.15 | L21: NA | M21: =((H21 * K21) / 1000)+(G21*J21)/1000 -> 0.75 | N21: NA | O21: NA
B22: Upstream emissions from sea transport | C22: =_xlfn.XLOOKUP(B22, tblConversions[Item], tblConversions[State], "" ) -> NA | D22: =_xlfn.XLOOKUP(B22, tblConversions[Item], tblConversions[Category], "") -> Scope 3 | E22: =_xlfn.XLOOKUP(B22, tblConversions[Item], tblConversions[Type], "") -> Upstream Transport | F22: =_xlfn.XLOOKUP(B22, tblConversions[Item], tblConversions[Unit], "") -> USD | G22: 0 | H22: 7000 | I22: =G22+H22 -> 7000 | J22: =_xlfn.XLOOKUP(B22, tblConversions[Item], tblConversions[Multiplier], 0) -> 0 | K22: =_xlfn.XLOOKUP(B22, tblConversions[Item], tblConversions[GHG Factor (t CO2e per Unit)], 0) -> 0.05 | L22: NA | M22: =((H22 * K22) / 1000)+(G22*J22)/1000 -> 0.35 | N22: NA | O22: NA
B23: Business Travel emissions from Flights | C23: =_xlfn.XLOOKUP(B23, tblConversions[Item], tblConversions[State], "" ) -> NA | D23: =_xlfn.XLOOKUP(B23, tblConversions[Item], tblConversions[Category], "") -> Scope 3 | E23: =_xlfn.XLOOKUP(B23, tblConversions[Item], tblConversions[Type], "") -> Business Travels | F23: =_xlfn.XLOOKUP(B23, tblConversions[Item], tblConversions[Unit], "") -> USD | G23: 0 | H23: 5000 | I23: =G23+H23 -> 5000 | J23: =_xlfn.XLOOKUP(B23, tblConversions[Item], tblConversions[Multiplier], 0) -> 0 | K23: =_xlfn.XLOOKUP(B23, tblConversions[Item], tblConversions[GHG Factor (t CO2e per Unit)], 0) -> 0.15 | L23: NA | M23: =((H23 * K23) / 1000)+(G23*J23)/1000 -> 0.75 | N23: NA | O23: NA
B24: Business Travel emissions from Road Transport | C24: =_xlfn.XLOOKUP(B24, tblConversions[Item], tblConversions[State], "" ) -> NA | D24: =_xlfn.XLOOKUP(B24, tblConversions[Item], tblConversions[Category], "") -> Scope 3 | E24: =_xlfn.XLOOKUP(B24, tblConversions[Item], tblConversions[Type], "") -> Business Travels | F24: =_xlfn.XLOOKUP(B24, tblConversions[Item], tblConversions[Unit], "") -> USD | G24: 0 | H24: 6000 | I24: =G24+H24 -> 6000 | J24: =_xlfn.XLOOKUP(B24, tblConversions[Item], tblConversions[Multiplier], 0) -> 0 | K24: =_xlfn.XLOOKUP(B24, tblConversions[Item], tblConversions[GHG Factor (t CO2e per Unit)], 0) -> 1.9836 | L24: NA | M24: =((H24 * K24) / 1000)+(G24*J24)/1000 -> 11.9016 | N24: NA | O24: NA
B25: Business Travel emissions from Rail Transport | C25: =_xlfn.XLOOKUP(B25, tblConversions[Item], tblConversions[State], "" ) -> NA | D25: =_xlfn.XLOOKUP(B25, tblConversions[Item], tblConversions[Category], "") -> Scope 3 | E25: =_xlfn.XLOOKUP(B25, tblConversions[Item], tblConversions[Type], "") -> Business Travels | F25: =_xlfn.XLOOKUP(B25, tblConversions[Item], tblConversions[Unit], "") -> USD | G25: 0 | H25: 9000 | I25: =G25+H25 -> 9000 | J25: =_xlfn.XLOOKUP(B25, tblConversions[Item], tblConversions[Multiplier], 0) -> 1 | K25: =_xlfn.XLOOKUP(B25, tblConversions[Item], tblConversions[GHG Factor (t CO2e per Unit)], 0) -> 0.7409532 | L25: NA | M25: =((H25 * K25) / 1000)+(G25*J25)/1000 -> 6.6685788 | N25: NA | O25: NA
B26: Carbon Credits | C26: =_xlfn.XLOOKUP(B26, tblConversions[Item], tblConversions[State], "" ) -> NA | D26: =_xlfn.XLOOKUP(B26, tblConversions[Item], tblConversions[Category], "") -> Removals | E26: =_xlfn.XLOOKUP(B26, tblConversions[Item], tblConversions[Type], "") -> GHG | F26: =_xlfn.XLOOKUP(B26, tblConversions[Item], tblConversions[Unit], "") -> tCO2e | G26: 0 | H26: 100 | I26: =G26+H26 -> 100 | J26: =_xlfn.XLOOKUP(B26, tblConversions[Item], tblConversions[Multiplier], 0) -> 0 | K26: =_xlfn.XLOOKUP(B26, tblConversions[Item], tblConversions[GHG Factor (t CO2e per Unit)], 0) -> -1000 | L26: NA | M26: =((H26 * K26) / 1000)+(G26*J26)/1000 -> -100 | N26: NA | O26: NA
C27: =_xlfn.XLOOKUP(B27, tblConversions[Item], tblConversions[State], "" )
A28: B.3 | B28: Pollution of Air, Water and Soil | C28: =_xlfn.XLOOKUP(B28, tblConversions[Item], tblConversions[State], "" )
B29: Pollutant Type | C29: =_xlfn.XLOOKUP(B29, tblConversions[Item], tblConversions[State], "" ) | G29: Pollutants generated | H29: NA | I29: Total Pollutants | K29: NA | L29: Total Pollutants | N29: Total Pollutants Generated | O29: NA
B30: Air pollutant Nitrogen Oxides (NOx) in kg | C30: =_xlfn.XLOOKUP(B30, tblConversions[Item], tblConversions[State], "" ) -> Gas | D30: =_xlfn.XLOOKUP(B30, tblConversions[Item], tblConversions[Category], "") -> Air Emission | E30: =_xlfn.XLOOKUP(B30, tblConversions[Item], tblConversions[Type], "") -> NOx | F30: =_xlfn.XLOOKUP(B30, tblConversions[Item], tblConversions[Unit], "") -> kg | G30: 50 | I30: =G30+H30 -> 50 | J30: =_xlfn.XLOOKUP(B30, tblConversions[Item], tblConversions[Multiplier], 0) -> 1 | K30: =_xlfn.XLOOKUP(D30, tblConversions[Item], tblConversions[GHG Factor (t CO2e per Unit)], 0) -> 0 | L30: =I30*J30 -> 50 | M30: =IF(E30="Renewable", 0, (I30 * K30) / 1000) -> 0 | N30: =G30*J30 -> 50 | O30: =H30*J30 -> 0
B31: Air pollutant Sulhur Oxides (SOx) in kg | C31: =_xlfn.XLOOKUP(B31, tblConversions[Item], tblConversions[State], "" ) -> Gas | D31: =_xlfn.XLOOKUP(B31, tblConversions[Item], tblConversions[Category], "") -> Air Emission | E31: =_xlfn.XLOOKUP(B31, tblConversions[Item], tblConversions[Type], "") -> SOx | F31: =_xlfn.XLOOKUP(B31, tblConversions[Item], tblConversions[Unit], "") -> kg | G31: 20 | I31: =G31+H31 -> 20 | J31: =_xlfn.XLOOKUP(B31, tblConversions[Item], tblConversions[Multiplier], 0) -> 1 | K31: =_xlfn.XLOOKUP(D31, tblConversions[Item], tblConversions[GHG Factor (t CO2e per Unit)], 0) -> 0 | L31: =I31*J31 -> 20 | M31: =IF(E31="Renewable", 0, (I31 * K31) / 1000) -> 0 | N31: =G31*J31 -> 20 | O31: =H31*J31 -> 0
B32: Particulate Matter (PM10/PM2.5) in kg | C32: =_xlfn.XLOOKUP(B32, tblConversions[Item], tblConversions[State], "" ) -> Particles | D32: =_xlfn.XLOOKUP(B32, tblConversions[Item], tblConversions[Category], "") -> Air Emission | E32: =_xlfn.XLOOKUP(B32, tblConversions[Item], tblConversions[Type], "") -> PM10/PM2.5 | F32: =_xlfn.XLOOKUP(B32, tblConversions[Item], tblConversions[Unit], "") -> kg | G32: 100 | I32: =G32+H32 -> 100 | J32: =_xlfn.XLOOKUP(B32, tblConversions[Item], tblConversions[Multiplier], 0) -> 1 | K32: =_xlfn.XLOOKUP(D32, tblConversions[Item], tblConversions[GHG Factor (t CO2e per Unit)], 0) -> 0 | L32: =I32*J32 -> 100 | M32: =IF(E32="Renewable", 0, (I32 * K32) / 1000) -> 0 | N32: =G32*J32 -> 100 | O32: =H32*J32 -> 0
B33: Emissions to water in kg (for e.g. Nitrates) | C33: =_xlfn.XLOOKUP(B33, tblConversions[Item], tblConversions[State], "" ) -> Liquid | D33: =_xlfn.XLOOKUP(B33, tblConversions[Item], tblConversions[Category], "") -> Water Emission | E33: =_xlfn.XLOOKUP(B33, tblConversions[Item], tblConversions[Type], "") -> Wastewater | F33: =_xlfn.XLOOKUP(B33, tblConversions[Item], tblConversions[Unit], "") -> kg | G33: 125 | I33: =G33+H33 -> 125 | J33: 1 | K33: 0 | L33: =I33*J33 -> 125 | M33: 0 | N33: =G33*J33 -> 125
C34: =_xlfn.XLOOKUP(B34, tblConversions[Item], tblConversions[State], "" )
A35: B.4 | B35: Climate Strategy and Goals | C35: =_xlfn.XLOOKUP(B35, tblConversions[Item], tblConversions[State], "" )
C36: =_xlfn.XLOOKUP(B36, tblConversions[Item], tblConversions[State], "" ) | G36: This section is updated manually | L36: GHG GOALS
B37: GHG reduction target and time frame (per cent per year) | C37: =_xlfn.XLOOKUP(B37, tblConversions[Item], tblConversions[State], "" ) | D37: Climate Goal | E37: GHG | F37: % / Year | G37: 0.1 | H37: NA | I37: NA | J37: NA | K37: NA | L37: =G37 -> 0.1 | M37: NA | N37: NA | O37: NA
B38: Financial effects from climate risks (in $US) | C38: =_xlfn.XLOOKUP(B38, tblConversions[Item], tblConversions[State], "" ) | D38: Climate Goal | E38: RISK | F38: Currency | G38: 250000 | H38: NA | I38: NA | J38: NA | K38: NA | L38: =G38 -> 250000 | M38: NA | N38: NA | O38: NA
B39: Investment allocated to transition plan (in $US) | C39: =_xlfn.XLOOKUP(B39, tblConversions[Item], tblConversions[State], "" ) | D39: Climate Goal | E39: INVESTMENT | F39: Currency | G39: 100000 | H39: NA | I39: NA | J39: NA | K39: NA | L39: =G39 -> 100000 | M39: NA | N39: NA | O39: NA
C40: =_xlfn.XLOOKUP(B40, tblConversions[Item], tblConversions[State], "" ) | H40: NA | I40: NA | J40: NA | K40: NA | L40: =G40 -> 0 | M40: NA | N40: NA | O40: NA
...

Sheet Conversions
A1: Item | B1: State | C1: Type | D1: Unit | E1: Category | F1: Multiplier | G1: GHG Factor (t CO2e per Unit) | H1: Remarks | I1: Source2
A2: Electricity (Grid) | B2: Energy | C2: Non-Renewable | D2: MWh | E2: Scope 2: Location | F2: 1 | G2: 0.81 | H2: Multiplier = Energy Factor (MWh per Unit) | I2: Grid / Supplier
A3: Heating | B3: Energy | C3: Non-Renewable | D3: m3 | E3: Scope 2: Market | F3: 1 | G3: 0
A4: Cooling | B4: Energy | C4: Non-Renewable | D4: m3 | E4: Scope 2: Market | F4: 1 | G4: 0
A5: Kerosene | B5: Liquid | C5: Non-Renewable | D5: Litres | E5: Scope 1 | F5: 0.0097 | G5: 2.518 | H5: Multiplier = Energy Factor (MWh per Unit) | I5: DEFRA 2024 / NSE
A6: Diesel | B6: Liquid | C6: Non-Renewable | D6: Litres | E6: Scope 1 | F6: 0.0106 | G6: 2.66155 | H6: Multiplier = Energy Factor (MWh per Unit) | I6: EPA/DEFRA 2024
A7: LPG | B7: Liquid | C7: Non-Renewable | D7: kg | E7: Scope 1 | F7: 0.0137 | G7: 2.93936 | H7: Multiplier = Energy Factor (MWh per Unit) | I7: EPA/DEFRA 2024
A8: Natural Gas | B8: Gas | C8: Non-Renewable | D8: m³ | E8: Scope 1 | F8: 0.0108 | G8: 2.04542 | H8: Multiplier = Energy Factor (MWh per Unit) | I8: EPA/DEFRA 2024
A9: On-Site Solar | B9: Energy | C9: Renewable | D9: MWh | E9: Scope 1 | F9: 1 | G9: 0 | H9: Multiplier = Energy Factor (MWh per Unit)
A10: On-Site Wind Electricity | B10: Energy | C10: Renewable | D10: MWh | E10: Scope 1 | F10: 1 | G10: 0 | H10: Multiplier = Energy Factor (MWh per Unit)
A11: Refrigerant (R-32) | B11: Liquid | C11: Direct Fugitive Emissions | D11: kg | E11: Scope 1 | F11: 0 | G11: 675 | H11: No Multiplier applied | I11: TERI
A12: Purchased Goods | B12: NA | C12: Purchased Goods | D12: USD | E12: Scope 3 | F12: 0 | G12: 0.45 | H12: GHG Factor
A13: Upstream emissions from road transport | B13: NA | C13: Upstream Transport | D13: USD | E13: Scope 3 | F13: 0 | G13: 1.9836 | H13: GHG Factor = EEIO emission factor for Truck (rigid, >3.5-7.5t) in kg CO2e/$
A14: Upstream emissions from air transport | B14: NA | C14: Upstream Transport | D14: USD | E14: Scope 3 | F14: 0 | G14: 0.15 | H14: GHG Factor = EEIO emission factor forAir (long haul) in kg CO2e/$
A15: Upstream emissions from sea transport | B15: NA | C15: Upstream Transport | D15: USD | E15: Scope 3 | F15: 0 | G15: 0.05 | H15: GHG Factor= EEIO emission factor for Container 2,000–2,999 TEU in kg CO2e/$
A16: Business travel emissions from Flights | B16: NA | C16: Business Travels | D16: USD | E16: Scope 3 | F16: 0 | G16: 0.15 | H16: GHG Factor= EEIO emission factor for air travel in kg CO2e/$
A17: Business Travel emissions from Road Transport | B17: NA | C17: Business Travels | D17: USD | E17: Scope 3 | F17: 0 | G17: 1.9836 | H17: GHG Factor = 1.35 (CAD value of 1$US)* 1.469337284 kgCO2e/cad (OpenIO-Canada v2.9 — Canadian EEIO — for passengers cars in Canadial Dollar. Final value in kgCO2e/$
A18: Business Travel emissions from Rail Transport | B18: NA | C18: Business Travels | D18: USD | E18: Scope 3 | F18: 1 | G18: 0.7409532 | H18: GHG Factor = 1.35 (CAD value of 1$US)* 0.5488542212 kgCO2e/cad (OpenIO-Canada v2.9 — Canadian EEIO — for rail travel in Canadial Dollar. Final value in kgCO2e/$
A19: Carbon Credits | B19: NA | C19: GHG | D19: tCO2e | E19: Removals | F19: 0 | G19: -1000 | H19: Negative value under GHG Factor is used to subtract carbon credits
A20: Air pollutant Nitrogen Oxides (NOx) in kg | B20: Gas | C20: NOx | D20: kg | E20: Air Emission | F20: 1 | G20: 0 | H20: Source is a type of pollutant. Change Multiplier to 1000 if value added in tonnes, else use 1 if emissions value is reported in kg
A21: Air pollutant Sulhur Oxides (SOx) in kg | B21: Gas | C21: SOx | D21: kg | E21: Air Emission | F21: 1 | G21: 0 | H21: Source is a type of pollutant. Change Multiplier to 1000 if value added in tonnes, else use 1 if emissions value is reported in kg
A22: Particulate Matter (PM10/PM2.5) in kg | B22: Particles | C22: PM10/PM2.5 | D22: kg | E22: Air Emission | F22: 1 | G22: 0 | H22: Source is a type of pollutant. Change Multiplier to 1000 if value added in tonnes, else use 1 if emissions value is reported in kg
A23: Emissions to water in kg (for e.g. Nitrates) | B23: Liquid | C23: Wastewater | D23: kg | E23: Water Emission | F23: 1 | G23: 0 | H23: For e.g. Nitrates
... A26: Municipal Water | B26: Liquid | C26: Water | D26: m3 | E26: Withdrawal | F26: 1 | G26: 0 | H26: Use 0.001 as multiplier to converts litres to m3
A27: Marine resources extracted and utilised (gravels, deep-sea minerals, seafood, etc) | B27: NA | C27: Resources | D27: Tonnes | E27: Resource Use | F27: 1 | G27: 0
A28: Sea Water Used | B28: Liquid | C28: Water | D28: m3 | E28: Withdrawal | F28: 1 | G28: 0 | H28: Use 0.001 as multiplier to converts litres to m3
A29: Wastewater | B29: Liquid | C29: Wastewater | D29: m3 | E29: Discharge | F29: 1 | G29: 0 | H29: Use 0.001 as multiplier to converts litres to m3
A30: Watewater to oceans | B30: Liquid | C30: Wastewater | D30: m3 | E30: Discharge | F30: 1 | G30: 0 | H30: Use 0.001 as multiplier to converts litres to m3
A31: PFAS (SVHC) in effluents | B31: Material | C31: Hazardous Waste | D31: tonne | E31: Water Emission | F31: 1 | G31: 0 | H31: To convert value into tonnes
A32: Paper and Cardboard | B32: Material | C32: Non-Hazardous Waste | D32: tonne | E32: Reused | F32: 1 | G32: 0.021
A33: Composite materials | B33: Material | C33: Non-Hazardous Waste | D33: tonne | E33: Landfilling | F33: 1 | G33: 1.2 | H33: Includes items like impregnated textile, elastomer, etc;
A34: Organic matter from natural products | B34: Material | C34: Non-Hazardous Waste | D34: tonne | E34: Landfilling | F34: 1 | G34: 1.2 | H34: For example, items likegrease, wax, etc;
A35: Solvents used in finishing (hazardous) | B35: Material | C35: Hazardous Waste | D35: tonne | E35: Incineration | F35: 1 | G35: 1.2
A36: Solvents used in finishing (non-hazardous) | B36: Material | C36: Non-Hazardous Waste | D36: tonne | E36: Landfilling | F36: 1 | G36: 1.2
A37: Dyestuffs and pigments containing hazardous substances | B37: Material | C37: Hazardous Waste | D37: tonne | E37: Incineration | F37: 1 | G37: 1.2
A38: Non-hazardous dyestuffs and pigments | B38: Material | C38: Non-Hazardous Waste | D38: tonne | E38: Landfilling | F38: 1 | G38: 1.2
A39: Sludges from on-site treatment (hazardous) | B39: Material | C39: Hazardous Waste | D39: tonne | E39: Incineration | F39: 1 | G39: 1.2
A40: Sludges from on-site treatment (non-hazardous) | B40: Material | C40: Non-Hazardous Waste | D40: tonne | E40: Landfilling | F40: 1 | G40: 1.2
A41: Unprocessed textile fibres | B41: Material | C41: Non-Hazardous Waste | D41: tonne | E41: Reused | F41: 1 | G41: 1.2
A42: Wastes from processed textile fibres | B42: Material | C42: Non-Hazardous Waste | D42: tonne | E42: Recycled | F42: 1 | G42: 1.2
...

Sheet ROUGH
B1: UNIT | C1: UNIT | D1: RECYCLED VS DISPOSED RATIO | E1: ACTUAL RATIO | F1: ROUNDED FIGURE
B2: cubic metres | C2: m3 | D2: RECYCLED | E2: =(SUM(Inputs!N63:N73, Inputs!N77:N80)) / GCD((SUM(Inputs!N63:N73, Inputs!N77:N80)), (SUM(Inputs!O63:O73, Inputs!O77:O80))) -> 7.505 | F2: 7.5
B3: Metric Tonnes | C3: MT | D3: DISPOSED | E3: =(SUM(Inputs!O63:O73, Inputs!O77:O80)) / GCD((SUM(Inputs!N63:N73, Inputs!N77:N80)), (SUM(Inputs!O63:O73, Inputs!O77:O80))) -> 5.1275 | F3: 5.1
B4: square meteres | C4: m2
C6: ERROR
C7: OK
